Workbook

Sheet All Data
A1: School ID | B1: School Name | C1: School Long Name | D1: Transfer Rate | E1: Governance | F1: Network | G1: Network Chief | H1: Effective Leaders Score | I1: Effective Leaders Rating | J1: ESB Subdist | K1: ESB Dist | L1: CBOE Representative | M1: Opportunity Index | N1: Full Address | O1: Partial Address | P1: Ward | Q1: Alderman
A2: 400153 | B2: ACERO - BRIGHTON PARK | C2: Acero Charter Schools - Brighton Park | D2: 0.04 | E2: Charter | F2: Charter | G2: =VLOOKUP(F2, 'Network Chiefs'!A:B, 2, FALSE) -> #N/A | H2: 56 | I2: Neutral | J2: 7b | K2: 7 | L2: {=INDEX('School Rep'!$A$2:$A$21, MATCH(J2, 'School Rep'!$B$2:$B$21, 0))} -> Yesenia Lopez | M2: 3.7 | N2: 4420 S Fairfield Ave | Chicago, IL 60632 | O2: =LEFT(N2, FIND("|", N2) - 1) -> 4420 S Fairfield Ave | P2: 12 | Q2: Ramirez, Julia M.
A3: 400101 | B3: ACERO - CISNEROS | C3: Acero Charter Schools - Sandra Cisneros | D3: 0.095 | E3: Charter | F3: Charter | G3: =VLOOKUP(F3, 'Network Chiefs'!A:B, 2, FALSE) -> #N/A | H3: 51 | I3: Neutral | J3: 8b | K3: 8 | L3: {=INDEX('School Rep'!$A$2:$A$21, MATCH(J3, 'School Rep'!$B$2:$B$21, 0))} -> Cydney Wallace | M3: 3.6 | N3: 2744 W Pershing Rd | Chicago, IL 60632 | O3: =LEFT(N3, FIND("|", N3) - 1) -> 2744 W Pershing Rd | P3: 12 | Q3: Ramirez, Julia M.
A4: 400120 | B4: ACERO - CLEMENTE | C4: Acero Charter Schools - Roberto Clemente | D4: 0.022 | E4: Charter | F4: Charter | G4: =VLOOKUP(F4, 'Network Chiefs'!A:B, 2, FALSE) -> #N/A | H4: 16 | I4: Very Weak | J4: 5a | K4: 5 | L4: {=INDEX('School Rep'!$A$2:$A$21, MATCH(J4, 'School Rep'!$B$2:$B$21, 0))} -> Aaron "Jitu" Brown | M4: 3.6 | N4: 2050 N Natchez Ave | Chicago, IL 60707 | O4: =LEFT(N4, FIND("|", N4) - 1) -> 2050 N Natchez Ave | P4: 29 | Q4: Taliaferro, Chris
A5: 400121 | B5: ACERO - DE LA CRUZ | C5: Acero Charter Schools - Sor Juana Inés de la Cruz | D5: 0.147 | E5: Charter | F5: Charter | G5: =VLOOKUP(F5, 'Network Chiefs'!A:B, 2, FALSE) -> #N/A | H5: 45 | I5: Neutral | J5: 2a | K5: 2 | L5: {=INDEX('School Rep'!$A$2:$A$21, MATCH(J5, 'School Rep'!$B$2:$B$21, 0))} -> Ebony DeBerry | M5: 3.2 | N5: 7416 N Ridge Ave | Chicago, IL 60645 | O5: =LEFT(N5, FIND("|", N5) - 1) -> 7416 N Ridge Ave | P5: 49 | Q5: Hadden, Maria E.
A6: 400081 | B6: ACERO - DE LAS CASAS | C6: Acero Charter Schools - Bartolomé de las Casas | D6: 0.064 | E6: Charter | F6: Charter | G6: =VLOOKUP(F6, 'Network Chiefs'!A:B, 2, FALSE) -> #N/A | H6: 32 | I6: Weak | J6: 7a | K6: 7 | L6: {=INDEX('School Rep'!$A$2:$A$21, MATCH(J6, 'School Rep'!$B$2:$B$21, 0))} -> Emma Lozano | M6: 3.4 | N6: 1641 W 16th St | Chicago, IL 60608 | O6: =LEFT(N6, FIND("|", N6) - 1) -> 1641 W 16th St | P6: 25 | Q6: Sigcho-Lopez, Byron
A7: 400082 | B7: ACERO - FUENTES | C7: Acero Charter Schools - Carlos Fuentes | D7: 0.051 | E7: Charter | F7: Charter | G7: =VLOOKUP(F7, 'Network Chiefs'!A:B, 2, FALSE) -> #N/A | H7: 42 | I7: Neutral | J7: 3a | K7: 3 | L7: {=INDEX('School Rep'!$A$2:$A$21, MATCH(J7, 'School Rep'!$B$2:$B$21, 0))} -> Norma Rios-Sierra | M7: 3.3 | N7: 2845 W Barry Ave | Chicago, IL 60618 | O7: =LEFT(N7, FIND("|", N7) - 1) -> 2845 W Barry Ave | P7: 35 | Q7: Ramirez-Rosa, Carlos
A8: 400085 | B8: ACERO - GARCIA HS | C8: Acero Charter Schools - Major Hector P. Garcia MD | D8: 0.072 | E8: Charter | F8: Charter | G8: =VLOOKUP(F8, 'Network Chiefs'!A:B, 2, FALSE) -> #N/A | H8: 60 | I8: Strong | J8: 7b | K8: 7 | L8: {=INDEX('School Rep'!$A$2:$A$21, MATCH(J8, 'School Rep'!$B$2:$B$21, 0))} -> Yesenia Lopez | M8: 3 | N8: 4248 W 47th St | Chicago, IL 60632 | O8: =LEFT(N8, FIND("|", N8) - 1) -> 4248 W 47th St | P8: 14 | Q8: Gutierrez, Jeylu B.
A9: 400112 | B9: ACERO - IDAR | C9: Acero Charter Schools - Jovita Idar | D9: 0.061 | E9: Charter | F9: Charter | G9: =VLOOKUP(F9, 'Network Chiefs'!A:B, 2, FALSE) -> #N/A | H9: 64 | I9: Strong | J9: 7b | K9: 7 | L9: {=INDEX('School Rep'!$A$2:$A$21, MATCH(J9, 'School Rep'!$B$2:$B$21, 0))} -> Yesenia Lopez | M9: 3.5 | N9: 5050 S Homan Ave | Chicago, IL 60632 | O9: =LEFT(N9, FIND("|", N9) - 1) -> 5050 S Homan Ave | P9: 14 | Q9: Gutierrez, Jeylu B.
A10: 400089 | B10: ACERO - MARQUEZ | C10: Acero Charter Schools - Officer Donald J. Marquez | D10: 0.059 | E10: Charter | F10: Charter | G10: =VLOOKUP(F10, 'Network Chiefs'!A:B, 2, FALSE) -> #N/A | H10: 46 | I10: Neutral | J10: 7b | K10: 7 | L10: {=INDEX('School Rep'!$A$2:$A$21, MATCH(J10, 'School Rep'!$B$2:$B$21, 0))} -> Yesenia Lopez | M10: 3.7 | N10: 2916 W 47th St | Chicago, IL 60632 | O10: =LEFT(N10, FIND("|", N10) - 1) -> 2916 W 47th St | P10: 12 | Q10: Ramirez, Julia M.
A11: 400083 | B11: ACERO - PAZ | C11: Acero Charter Schools - Octavio Paz Campus | D11: 0.057 | E11: Charter | F11: Charter | G11: =VLOOKUP(F11, 'Network Chiefs'!A:B, 2, FALSE) -> #N/A | H11: 33 | I11: Weak | J11: 7a | K11: 7 | L11: {=INDEX('School Rep'!$A$2:$A$21, MATCH(J11, 'School Rep'!$B$2:$B$21, 0))} -> Emma Lozano | M11: 3.8 | N11: 2651 W 23rd St | Chicago, IL 60608 | O11: =LEFT(N11, FIND("|", N11) - 1) -> 2651 W 23rd St | P11: 25 | Q11: Sigcho-Lopez, Byron
A12: 400114 | B12: ACERO - SANTIAGO | C12: Acero Charter Schools - Esmeralda Santiago | D12: 0.095 | E12: Charter | F12: Charter | G12: =VLOOKUP(F12, 'Network Chiefs'!A:B, 2, FALSE) -> #N/A | H12: 55 | I12: Neutral | J12: 5a | K12: 5 | L12: {=INDEX('School Rep'!$A$2:$A$21, MATCH(J12, 'School Rep'!$B$2:$B$21, 0))} -> Aaron "Jitu" Brown | M12: 3.4 | N12: 2510 W Cortez St | Chicago, IL 60622 | O12: =LEFT(N12, FIND("|", N12) - 1) -> 2510 W Cortez St | P12: 36 | Q12: Villegas, Gilbert
A13: 400149 | B13: ACERO - SOTO HS | C13: Acero Charter Schools - Victoria Soto | D13: 0.065 | E13: Charter | F13: Charter | G13: =VLOOKUP(F13, 'Network Chiefs'!A:B, 2, FALSE) -> #N/A | H13: 65 | I13: Strong | J13: 7b | K13: 7 | L13: {=INDEX('School Rep'!$A$2:$A$21, MATCH(J13, 'School Rep'!$B$2:$B$21, 0))} -> Yesenia Lopez | M13: 3 | N13: 5025 S St. Louis Ave | Chicago, IL 60632 | O13: =LEFT(N13, FIND("|", N13) - 1) -> 5025 S St. Louis Ave | P13: 14 | Q13: Gutierrez, Jeylu B.
... A44: 609792 | B44: BATEMAN | C44: Newton Bateman Elementary School | D44: 0.072 | E44: District | F44: Network 1 | G44: =VLOOKUP(F44, 'Network Chiefs'!A:B, 2, FALSE) -> Julie McGlade | H44: 67 | I44: Strong | J44: 2b | K44: 2 | L44: {=INDEX('School Rep'!$A$2:$A$21, MATCH(J44, 'School Rep'!$B$2:$B$21, 0))} -> Debby Pope | M44: 2.3 | N44: 4220 N Richmond St | Chicago, IL 60618 | O44: =LEFT(N44, FIND("|", N44) - 1) -> 4220 N Richmond St | P44: 33 | Q44: Rodriguez Sanchez, Rossana
A45: 610083 | B45: BEARD | C45: Daniel C Beard Elementary School | D45: 0.133 | E45: District | F45: Network 1 | G45: =VLOOKUP(F45, 'Network Chiefs'!A:B, 2, FALSE) -> Julie McGlade | J45: 1a | K45: 1 | L45: {=INDEX('School Rep'!$A$2:$A$21, MATCH(J45, 'School Rep'!$B$2:$B$21, 0))} -> Ed Bannon | M45: 2.2 | N45: 6445 W Strong St | Chicago, IL 60656 | O45: =LEFT(N45, FIND("|", N45) - 1) -> 6445 W Strong St | P45: 41 | Q45: Napolitano, Anthony V.
A46: 610246 | B46: BEASLEY | C46: Edward Beasley Elementary Magnet Academic Center | D46: 0.043 | E46: District | F46: Network 9 | G46: =VLOOKUP(F46, 'Network Chiefs'!A:B, 2, FALSE) -> Alene Mason | H46: 58 | I46: Neutral | J46: 6b | K46: 6 | L46: {=INDEX('School Rep'!$A$2:$A$21, MATCH(J46, 'School Rep'!$B$2:$B$21, 0))} -> Jessica Biggs | M46: 3.1 | N46: 5255 S State St | Chicago, IL 60609 | O46: =LEFT(N46, FIND("|", N46) - 1) -> 5255 S State St | P46: 3 | Q46: Dowell, Pat
A47: 609796 | B47: BEAUBIEN | C47: Jean Baptiste Beaubien Elementary School | D47: 0.052 | E47: District | F47: Network 1 | G47: =VLOOKUP(F47, 'Network Chiefs'!A:B, 2, FALSE) -> Julie McGlade | H47: 56 | I47: Neutral | J47: 1a | K47: 1 | L47: {=INDEX('School Rep'!$A$2:$A$21, MATCH(J47, 'School Rep'!$B$2:$B$21, 0))} -> Ed Bannon | M47: 2 | N47: 5025 N Laramie Ave | Chicago, IL 60630 | O47: =LEFT(N47, FIND("|", N47) - 1) -> 5025 N Laramie Ave | P47: 45 | Q47: Gardiner, James M.
A48: 610237 | B48: BEETHOVEN | C48: Ludwig Van Beethoven Elementary School | D48: 0.277 | E48: District | F48: Network 9 | G48: =VLOOKUP(F48, 'Network Chiefs'!A:B, 2, FALSE) -> Alene Mason | H48: 39 | I48: Weak | J48: 6b | K48: 6 | L48: {=INDEX('School Rep'!$A$2:$A$21, MATCH(J48, 'School Rep'!$B$2:$B$21, 0))} -> Jessica Biggs | M48: 3.2 | N48: 25 W 47th St | Chicago, IL 60609 | O48: =LEFT(N48, FIND("|", N48) - 1) -> 25 W 47th St | P48: 3 | Q48: Dowell, Pat
A49: 609797 | B49: BEIDLER | C49: Jacob Beidler Elementary School | D49: 0.154 | E49: District | F49: Network 5 | G49: =VLOOKUP(F49, 'Network Chiefs'!A:B, 2, FALSE) -> Shontae Higginbottom | H49: 51 | I49: Neutral | J49: 5b | K49: 5 | L49: {=INDEX('School Rep'!$A$2:$A$21, MATCH(J49, 'School Rep'!$B$2:$B$21, 0))} -> Michilla Blaise | M49: 2.8 | N49: 3151 W Walnut St | Chicago, IL 60612 | O49: =LEFT(N49, FIND("|", N49) - 1) -> 3151 W Walnut St | P49: 27 | Q49: Burnett, Jr., Walter
A50: 609798 | B50: BELDING | C50: Hiram H Belding Elementary School | D50: 0.072 | E50: District | F50: Network 1 | G50: =VLOOKUP(F50, 'Network Chiefs'!A:B, 2, FALSE) -> Julie McGlade | H50: 77 | I50: Strong | J50: 1b | K50: 1 | L50: {=INDEX('School Rep'!$A$2:$A$21, MATCH(J50, 'School Rep'!$B$2:$B$21, 0))} -> Jennifer Custer | M50: 2.2 | N50: 4257 N Tripp Ave | Chicago, IL 60641 | O50: =LEFT(N50, FIND("|", N50) - 1) -> 4257 N Tripp Ave | P50: 39 | Q50: Nugent, Samantha
A51: 609799 | B51: BELL | C51: Alexander Graham Bell Elementary School | D51: 0.017 | E51: District | F51: Network 4 | G51: =VLOOKUP(F51, 'Network Chiefs'!A:B, 2, FALSE) -> Jerry Travlos | H51: 41 | I51: Neutral | J51: 4b | K51: 4 | L51: {=INDEX('School Rep'!$A$2:$A$21, MATCH(J51, 'School Rep'!$B$2:$B$21, 0))} -> Ellen Rosenfeld | M51: 1.3 | N51: 3730 N Oakley Ave | Chicago, IL 60618 | O51: =LEFT(N51, FIND("|", N51) - 1) -> 3730 N Oakley Ave | P51: 47 | Q51: Martin, Matthew J.
A52: 609922 | B52: BELMONT-CRAGIN | C52: Belmont-Cragin Elementary School | D52: 0.082 | E52: District | F52: Network 3 | G52: =VLOOKUP(F52, 'Network Chiefs'!A:B, 2, FALSE) -> Jennifer Farrell‐Rottman | H52: 55 | I52: Neutral | J52: 3b | K52: 3 | L52: {=INDEX('School Rep'!$A$2:$A$21, MATCH(J52, 'School Rep'!$B$2:$B$21, 0))} -> Carlos Rivas | M52: 3.3 | N52: 5252 W Palmer St | Chicago, IL 60639 | O52: =LEFT(N52, FIND("|", N52) - 1) -> 5252 W Palmer St | P52: 36 | Q52: Villegas, Gilbert
A53: 609800 | B53: BENNETT | C53: Frank I Bennett Elementary School | D53: 0.144 | E53: District | F53: Network 13 | G53: =VLOOKUP(F53, 'Network Chiefs'!A:B, 2, FALSE) -> Dr. Terrycita D. Perry | H53: 51 | I53: Neutral | J53: 9b | K53: 9 | L53: {=INDEX('School Rep'!$A$2:$A$21, MATCH(J53, 'School Rep'!$B$2:$B$21, 0))} -> Therese Boyle | M53: 2.8 | N53: 10115 S Prairie Ave | Chicago, IL 60628 | O53: =LEFT(N53, FIND("|", N53) - 1) -> 10115 S Prairie Ave | P53: 9 | Q53: Beale, Anthony
A54: 610350 | B54: BLACK | C54: Robert A Black Magnet Elementary School | D54: 0.028 | E54: District | F54: Network 12 | G54: =VLOOKUP(F54, 'Network Chiefs'!A:B, 2, FALSE) -> Shenethe Parks | H54: 62 | I54: Strong | J54: 10b | K54: 10 | L54: {=INDEX('School Rep'!$A$2:$A$21, MATCH(J54, 'School Rep'!$B$2:$B$21, 0))} -> Olga Bautista | M54: 2.7 | N54: 9101 S Euclid Ave | Chicago, IL 60617 | O54: =LEFT(N54, FIND("|", N54) - 1) -> 9101 S Euclid Ave | P54: 8 | Q54: Harris, Michelle A.
A55: 609803 | B55: BLAINE | C55: James G Blaine Elementary School | D55: 0.041 | E55: District | F55: Network 4 | G55: =VLOOKUP(F55, 'Network Chiefs'!A:B, 2, FALSE) -> Jerry Travlos | H55: 56 | I55: Neutral | J55: 4a | K55: 4 | L55: {=INDEX('School Rep'!$A$2:$A$21, MATCH(J55, 'School Rep'!$B$2:$B$21, 0))} -> Karen Zaccor | M55: 1.8 | N55: 1420 W Grace St | Chicago, IL 60613 | O55: =LEFT(N55, FIND("|", N55) - 1) -> 1420 W Grace St | P55: 46 | Q55: Clay, Angela
A56: 610087 | B56: BLAIR | C56: Blair Early Childhood Center | D56: 0 | E56: District | F56: Network 10 | G56: =VLOOKUP(F56, 'Network Chiefs'!A:B, 2, FALSE) -> Mira Weber | H56: 89 | I56: Very Strong | J56: 8a | K56: 8 | L56: {=INDEX('School Rep'!$A$2:$A$21, MATCH(J56, 'School Rep'!$B$2:$B$21, 0))} -> Angel Gutierrez | M56: 2.2 | N56: 6751 W 63rd Pl | Chicago, IL 60638 | O56: =LEFT(N56, FIND("|", N56) - 1) -> 6751 W 63rd Pl | P56: 13 | Q56: Quinn, Marty
A57: 609698 | B57: BOGAN HS | C57: William J Bogan High School | D57: 0.184 | E57: District | F57: Network 16 | G57: =VLOOKUP(F57, 'Network Chiefs'!A:B, 2, FALSE) -> Devon LaRosa | H57: 54 | I57: Neutral | J57: 8a | K57: 8 | L57: {=INDEX('School Rep'!$A$2:$A$21, MATCH(J57, 'School Rep'!$B$2:$B$21, 0))} -> Angel Gutierrez | M57: 3.2 | N57: 3939 W 79th St | Chicago, IL 60652 | O57: =LEFT(N57, FIND("|", N57) - 1) -> 3939 W 79th St | P57: 18 | Q57: Curtis, Derrick G.
... A95: 609849 | B95: CASSELL | C95: George F Cassell Elementary School | D95: 0.031 | E95: District | F95: ISP | G95: =VLOOKUP(F95, 'Network Chiefs'!A:B, 2, FALSE) -> #N/A | H95: 84 | I95: Very Strong | J95: 9b | K95: 9 | L95: {=INDEX('School Rep'!$A$2:$A$21, MATCH(J95, 'School Rep'!$B$2:$B$21, 0))} -> Therese Boyle | M95: 2 | N95: 11314 S Spaulding Ave | Chicago, IL 60655 | O95: =LEFT(N95, FIND("|", N95) - 1) -> 11314 S Spaulding Ave | P95: 19 | Q95: O'Shea, Matthew J.
A96: 610599 | B96: CATALPA | C96: Catalpa Early Childhood Center | D96: 0 | E96: District | F96: Network 1 | G96: =VLOOKUP(F96, 'Network Chiefs'!A:B, 2, FALSE) -> Julie McGlade | J96: Not Found | K96: Not Found | L96: Not Found | M96: 1.8 | N96: 5252 N Long Ave | Chicago, IL 60630 | O96: =LEFT(N96, FIND("|", N96) - 1) -> 5252 N Long Ave | P96: 45 | Q96: Gardiner, James M.
A97: 400021 | B97: CATALYST - CIRCLE ROCK | C97: Catalyst Elementary Charter School - Circle Rock | D97: 0.025 | E97: Charter | F97: Charter | G97: =VLOOKUP(F97, 'Network Chiefs'!A:B, 2, FALSE) -> #N/A | H97: 64 | I97: Strong | J97: 5a | K97: 5 | L97: {=INDEX('School Rep'!$A$2:$A$21, MATCH(J97, 'School Rep'!$B$2:$B$21, 0))} -> Aaron "Jitu" Brown | M97: 3.5 | N97: 5608 W Washington Blvd | Chicago, IL 60644 | O97: =LEFT(N97, FIND("|", N97) - 1) -> 5608 W Washington Blvd | P97: 29 | Q97: Taliaferro, Chris
A98: 400115 | B98: CATALYST - MARIA | C98: Catalyst - Maria Charter School | D98: 0.053 | E98: Charter | F98: Charter | G98: =VLOOKUP(F98, 'Network Chiefs'!A:B, 2, FALSE) -> #N/A | H98: 46 | I98: Neutral | J98: Not Found | K98: Not Found | L98: Not Found | M98: 3.1 | N98: 6727 S California Ave | Chicago, IL 60629 | O98: =LEFT(N98, FIND("|", N98) - 1) -> 6727 S California Ave | P98: 16 | Q98: Coleman, Stephanie D.
A99: 400182 | B99: CATALYST MARIA HS | G99: =VLOOKUP(F99, 'Network Chiefs'!A:B, 2, FALSE) -> #N/A | H99: 46 | I99: Neutral | J99: Not Found | K99: Not Found | L99: Not Found | M99: 3 | N99: 6727 S California Ave | Chicago, IL 60629 | O99: =LEFT(N99, FIND("|", N99) - 1) -> 6727 S California Ave | P99: 16 | Q99: Coleman, Stephanie D.
A100: 610251 | B100: CATHER | C100: Willa Cather Elementary School | D100: 0.181 | E100: District | F100: Network 5 | G100: =VLOOKUP(F100, 'Network Chiefs'!A:B, 2, FALSE) -> Shontae Higginbottom | H100: 54 | I100: Neutral | J100: 5b | K100: 5 | L100: {=INDEX('School Rep'!$A$2:$A$21, MATCH(J100, 'School Rep'!$B$2:$B$21, 0))} -> Michilla Blaise | M100: 3.6 | N100: 2908 W Washington Blvd | Chicago, IL 60612 | O100: =LEFT(N100, FIND("|", N100) - 1) -> 2908 W Washington Blvd | P100: 27 | Q100: Burnett, Jr., Walter
A101: 609851 | B101: CHALMERS | C101: Thomas Chalmers STEAM Elementary School | D101: 0.176 | E101: District | F101: Network 5 | G101: =VLOOKUP(F101, 'Network Chiefs'!A:B, 2, FALSE) -> Shontae Higginbottom | H101: 28 | I101: Weak | J101: 5b | K101: 5 | L101: {=INDEX('School Rep'!$A$2:$A$21, MATCH(J101, 'School Rep'!$B$2:$B$21, 0))} -> Michilla Blaise | M101: 3.8 | N101: 2745 W Roosevelt Rd | Chicago, IL 60608 | O101: =LEFT(N101, FIND("|", N101) - 1) -> 2745 W Roosevelt Rd | P101: 28 | Q101: Ervin, Jason C.
A102: 609852 | B102: CHAPPELL | C102: Eliza Chappell Elementary School | D102: 0.06 | E102: District | F102: Network 2 | G102: =VLOOKUP(F102, 'Network Chiefs'!A:B, 2, FALSE) -> Marilou Rebolledo | H102: 45 | I102: Neutral | J102: 2b | K102: 2 | L102: {=INDEX('School Rep'!$A$2:$A$21, MATCH(J102, 'School Rep'!$B$2:$B$21, 0))} -> Debby Pope | M102: 2.3 | N102: 2135 W Foster Ave | Chicago, IL 60625 | O102: =LEFT(N102, FIND("|", N102) - 1) -> 2135 W Foster Ave | P102: 40 | Q102: Vasquez, Jr., Andre
A103: 609853 | B103: CHASE | C103: Salmon P Chase Elementary School | D103: 0.066 | E103: District | F103: Network 4 | G103: =VLOOKUP(F103, 'Network Chiefs'!A:B, 2, FALSE) -> Jerry Travlos | H103: 55 | I103: Neutral | J103: 3b | K103: 3 | L103: {=INDEX('School Rep'!$A$2:$A$21, MATCH(J103, 'School Rep'!$B$2:$B$21, 0))} -> Carlos Rivas | M103: 2.2 | N103: 2021 N Point St | Chicago, IL 60647 | O103: =LEFT(N103, FIND("|", N103) - 1) -> 2021 N Point St | P103: 1 | Q103: La Spata, Daniel
A104: 610148 | B104: CHAVEZ | C104: Cesar E Chavez Multicultural Academic Center | D104: 0.05 | E104: District | F104: ISP | G104: =VLOOKUP(F104, 'Network Chiefs'!A:B, 2, FALSE) -> #N/A | H104: 73 | I104: Strong | J104: 8b | K104: 8 | L104: {=INDEX('School Rep'!$A$2:$A$21, MATCH(J104, 'School Rep'!$B$2:$B$21, 0))} -> Cydney Wallace | M104: 3.7 | N104: 4747 S Marshfield Ave | Chicago, IL 60609 | O104: =LEFT(N104, FIND("|", N104) - 1) -> 4747 S Marshfield Ave | P104: 20 | Q104: Taylor, Jeanette B.
A105: 400022 | B105: CHIARTS HS | C105: Chicago High School for the Arts (ChiArts) | D105: 0.031 | E105: Contract | F105: Contract | G105: =VLOOKUP(F105, 'Network Chiefs'!A:B, 2, FALSE) -> #N/A | H105: 21 | I105: Weak | J105: 3b | K105: 3 | L105: {=INDEX('School Rep'!$A$2:$A$21, MATCH(J105, 'School Rep'!$B$2:$B$21, 0))} -> Carlos Rivas | M105: 2 | N105: 2714 W Augusta Blvd | Chicago, IL 60622 | O105: =LEFT(N105, FIND("|", N105) - 1) -> 2714 W Augusta Blvd | P105: 26 | Q105: Fuentes, Jessica L.
A106: 610248 | B106: CHICAGO ACADEMY ES | C106: Chicago Academy Elementary School | D106: 0.02 | E106: District | F106: Network 1 | G106: =VLOOKUP(F106, 'Network Chiefs'!A:B, 2, FALSE) -> Julie McGlade | H106: 63 | I106: Strong | J106: 1b | K106: 1 | L106: {=INDEX('School Rep'!$A$2:$A$21, MATCH(J106, 'School Rep'!$B$2:$B$21, 0))} -> Jennifer Custer | M106: 2.7 | N106: 3400 N Austin Ave | Chicago, IL 60634 | O106: =LEFT(N106, FIND("|", N106) - 1) -> 3400 N Austin Ave | P106: 30 | Q106: Cruz, Ruth
A107: 610340 | B107: CHICAGO ACADEMY HS | C107: Chicago Academy High School | D107: 0.031 | E107: District | F107: Network 14 | G107: =VLOOKUP(F107, 'Network Chiefs'!A:B, 2, FALSE) -> Dr. Laura LeMone | H107: 63 | I107: Strong | J107: 1b | K107: 1 | L107: {=INDEX('School Rep'!$A$2:$A$21, MATCH(J107, 'School Rep'!$B$2:$B$21, 0))} -> Jennifer Custer | M107: 2.6 | N107: 3400 N Austin Ave | Chicago, IL 60634 | O107: =LEFT(N107, FIND("|", N107) - 1) -> 3400 N Austin Ave | P107: 30 | Q107: Cruz, Ruth
...

Sheet Copy of All Data
A1: School ID | B1: School Name | C1: School Long Name | D1: Transfer Rate | E1: Governance | F1: Network | G1: Network Chief | H1: Effective Leaders Score | I1: Effective Leaders Rating | J1: ESB Subdist | K1: ESB Dist | L1: CBOE Representative | M1: Opportunity Index | N1: Full Address | O1: Partial Address | P1: Ward | Q1: Alderman
A2: 400153 | B2: ACERO - BRIGHTON PARK | C2: Acero Charter Schools - Brighton Park | D2: 0.04 | E2: Charter | F2: Charter | G2: #N/A | H2: 56 | I2: Neutral | J2: 7b | K2: 7 | L2: {=INDEX('School Rep'!$A$2:$A$21, MATCH(J2, 'School Rep'!$B$2:$B$21, 0))} -> Yesenia Lopez | M2: 3.7 | N2: 4420 S Fairfield Ave | Chicago, IL 60632 | O2: =LEFT(N2, FIND("|", N2) - 1) -> 4420 S Fairfield Ave | P2: 12 | Q2: Ramirez, Julia M.
A3: 400101 | B3: ACERO - CISNEROS | C3: Acero Charter Schools - Sandra Cisneros | D3: 0.095 | E3: Charter | F3: Charter | G3: #N/A | H3: 51 | I3: Neutral | J3: 8b | K3: 8 | L3: {=INDEX('School Rep'!$A$2:$A$21, MATCH(J3, 'School Rep'!$B$2:$B$21, 0))} -> Cydney Wallace | M3: 3.6 | N3: 2744 W Pershing Rd | Chicago, IL 60632 | O3: =LEFT(N3, FIND("|", N3) - 1) -> 2744 W Pershing Rd | P3: 12 | Q3: Ramirez, Julia M.
A4: 400120 | B4: ACERO - CLEMENTE | C4: Acero Charter Schools - Roberto Clemente | D4: 0.022 | E4: Charter | F4: Charter | G4: #N/A | H4: 16 | I4: Very Weak | J4: 5a | K4: 5 | L4: {=INDEX('School Rep'!$A$2:$A$21, MATCH(J4, 'School Rep'!$B$2:$B$21, 0))} -> Aaron "Jitu" Brown | M4: 3.6 | N4: 2050 N Natchez Ave | Chicago, IL 60707 | O4: =LEFT(N4, FIND("|", N4) - 1) -> 2050 N Natchez Ave | P4: 29 | Q4: Taliaferro, Chris
A5: 400121 | B5: ACERO - DE LA CRUZ | C5: Acero Charter Schools - Sor Juana Inés de la Cruz | D5: 0.147 | E5: Charter | F5: Charter | G5: #N/A | H5: 45 | I5: Neutral | J5: 2a | K5: 2 | L5: {=INDEX('School Rep'!$A$2:$A$21, MATCH(J5, 'School Rep'!$B$2:$B$21, 0))} -> Ebony DeBerry | M5: 3.2 | N5: 7416 N Ridge Ave | Chicago, IL 60645 | O5: =LEFT(N5, FIND("|", N5) - 1) -> 7416 N Ridge Ave | P5: 49 | Q5: Hadden, Maria E.
A6: 400081 | B6: ACERO - DE LAS CASAS | C6: Acero Charter Schools - Bartolomé de las Casas | D6: 0.064 | E6: Charter | F6: Charter | G6: #N/A | H6: 32 | I6: Weak | J6: 7a | K6: 7 | L6: {=INDEX('School Rep'!$A$2:$A$21, MATCH(J6, 'School Rep'!$B$2:$B$21, 0))} -> Emma Lozano | M6: 3.4 | N6: 1641 W 16th St | Chicago, IL 60608 | O6: =LEFT(N6, FIND("|", N6) - 1) -> 1641 W 16th St | P6: 25 | Q6: Sigcho-Lopez, Byron
A7: 400082 | B7: ACERO - FUENTES | C7: Acero Charter Schools - Carlos Fuentes | D7: 0.051 | E7: Charter | F7: Charter | G7: #N/A | H7: 42 | I7: Neutral | J7: 3a | K7: 3 | L7: {=INDEX('School Rep'!$A$2:$A$21, MATCH(J7, 'School Rep'!$B$2:$B$21, 0))} -> Norma Rios-Sierra | M7: 3.3 | N7: 2845 W Barry Ave | Chicago, IL 60618 | O7: =LEFT(N7, FIND("|", N7) - 1) -> 2845 W Barry Ave | P7: 35 | Q7: Ramirez-Rosa, Carlos
A8: 400085 | B8: ACERO - GARCIA HS | C8: Acero Charter Schools - Major Hector P. Garcia MD | D8: 0.072 | E8: Charter | F8: Charter | G8: #N/A | H8: 60 | I8: Strong | J8: 7b | K8: 7 | L8: {=INDEX('School Rep'!$A$2:$A$21, MATCH(J8, 'School Rep'!$B$2:$B$21, 0))} -> Yesenia Lopez | M8: 3 | N8: 4248 W 47th St | Chicago, IL 60632 | O8: =LEFT(N8, FIND("|", N8) - 1) -> 4248 W 47th St | P8: 14 | Q8: Gutierrez, Jeylu B.
A9: 400112 | B9: ACERO - IDAR | C9: Acero Charter Schools - Jovita Idar | D9: 0.061 | E9: Charter | F9: Charter | G9: #N/A | H9: 64 | I9: Strong | J9: 7b | K9: 7 | L9: {=INDEX('School Rep'!$A$2:$A$21, MATCH(J9, 'School Rep'!$B$2:$B$21, 0))} -> Yesenia Lopez | M9: 3.5 | N9: 5050 S Homan Ave | Chicago, IL 60632 | O9: =LEFT(N9, FIND("|", N9) - 1) -> 5050 S Homan Ave | P9: 14 | Q9: Gutierrez, Jeylu B.
A10: 400089 | B10: ACERO - MARQUEZ | C10: Acero Charter Schools - Officer Donald J. Marquez | D10: 0.059 | E10: Charter | F10: Charter | G10: #N/A | H10: 46 | I10: Neutral | J10: 7b | K10: 7 | L10: {=INDEX('School Rep'!$A$2:$A$21, MATCH(J10, 'School Rep'!$B$2:$B$21, 0))} -> Yesenia Lopez | M10: 3.7 | N10: 2916 W 47th St | Chicago, IL 60632 | O10: =LEFT(N10, FIND("|", N10) - 1) -> 2916 W 47th St | P10: 12 | Q10: Ramirez, Julia M.
A11: 400083 | B11: ACERO - PAZ | C11: Acero Charter Schools - Octavio Paz Campus | D11: 0.057 | E11: Charter | F11: Charter | G11: #N/A | H11: 33 | I11: Weak | J11: 7a | K11: 7 | L11: {=INDEX('School Rep'!$A$2:$A$21, MATCH(J11, 'School Rep'!$B$2:$B$21, 0))} -> Emma Lozano | M11: 3.8 | N11: 2651 W 23rd St | Chicago, IL 60608 | O11: =LEFT(N11, FIND("|", N11) - 1) -> 2651 W 23rd St | P11: 25 | Q11: Sigcho-Lopez, Byron
A12: 400114 | B12: ACERO - SANTIAGO | C12: Acero Charter Schools - Esmeralda Santiago | D12: 0.095 | E12: Charter | F12: Charter | G12: #N/A | H12: 55 | I12: Neutral | J12: 5a | K12: 5 | L12: {=INDEX('School Rep'!$A$2:$A$21, MATCH(J12, 'School Rep'!$B$2:$B$21, 0))} -> Aaron "Jitu" Brown | M12: 3.4 | N12: 2510 W Cortez St | Chicago, IL 60622 | O12: =LEFT(N12, FIND("|", N12) - 1) -> 2510 W Cortez St | P12: 36 | Q12: Villegas, Gilbert
A13: 400149 | B13: ACERO - SOTO HS | C13: Acero Charter Schools - Victoria Soto | D13: 0.065 | E13: Charter | F13: Charter | G13: #N/A | H13: 65 | I13: Strong | J13: 7b | K13: 7 | L13: {=INDEX('School Rep'!$A$2:$A$21, MATCH(J13, 'School Rep'!$B$2:$B$21, 0))} -> Yesenia Lopez | M13: 3 | N13: 5025 S St. Louis Ave | Chicago, IL 60632 | O13: =LEFT(N13, FIND("|", N13) - 1) -> 5025 S St. Louis Ave | P13: 14 | Q13: Gutierrez, Jeylu B.
... A16: 400079 | B16: ACERO - ZIZUMBO | C16: Acero Charter Schools - SPC Daniel Zizumbo | D16: 0.036 | E16: Charter | F16: Charter | G16: #N/A | H16: 60 | I16: Strong | J16: 7b | K16: 7 | L16: {=INDEX('School Rep'!$A$2:$A$21, MATCH(J16, 'School Rep'!$B$2:$B$21, 0))} -> Yesenia Lopez | M16: 3.1 | N16: 4248 W 47th St | Chicago, IL 60632 | O16: =LEFT(N16, FIND("|", N16) - 1) -> 4248 W 47th St | P16: 14 | Q16: Gutierrez, Jeylu B.
A17: 609772 | B17: ADDAMS | C17: Jane Addams Elementary School | D17: 0.032 | E17: District | F17: Network 13 | G17: Dr. Terrycita D. Perry | H17: 55 | I17: Neutral | J17: 10b | K17: 10 | L17: {=INDEX('School Rep'!$A$2:$A$21, MATCH(J17, 'School Rep'!$B$2:$B$21, 0))} -> Olga Bautista | M17: 2.8 | N17: 10810 S Avenue H | Chicago, IL 60617 | O17: =LEFT(N17, FIND("|", N17) - 1) -> 10810 S Avenue H | P17: 10 | Q17: Chico, Peter
A18: 400060 | B18: AHS - PASSAGES | C18: Asian Human Services - Passages Charter School | D18: 0.183 | E18: Charter | F18: Charter | G18: #N/A | H18: 29 | I18: Weak | J18: 2b | K18: 2 | L18: {=INDEX('School Rep'!$A$2:$A$21, MATCH(J18, 'School Rep'!$B$2:$B$21, 0))} -> Debby Pope | M18: 2.6 | N18: 1643 W Bryn Mawr Ave | Chicago, IL 60660 | O18: =LEFT(N18, FIND("|", N18) - 1) -> 1643 W Bryn Mawr Ave | P18: 40 | Q18: Vasquez, Jr., Andre
A19: 610513 | B19: AIR FORCE HS | C19: Air Force Academy High School | D19: 0 | E19: District | F19: Network 16 | G19: Devon LaRosa | H19: 39 | I19: Weak | J19: 8b | K19: 8 | L19: {=INDEX('School Rep'!$A$2:$A$21, MATCH(J19, 'School Rep'!$B$2:$B$21, 0))} -> Cydney Wallace | M19: 3.2 | N19: 3630 S Wells St | Chicago, IL 60609 | O19: =LEFT(N19, FIND("|", N19) - 1) -> 3630 S Wells St | P19: 11 | Q19: Lee, Nicole T.
A20: 610212 | B20: ALBANY PARK | C20: Albany Park Multicultural Academy | D20: 0.087 | E20: District | F20: Network 1 | G20: Julie McGlade | H20: 71 | I20: Strong | J20: 2b | K20: 2 | L20: {=INDEX('School Rep'!$A$2:$A$21, MATCH(J20, 'School Rep'!$B$2:$B$21, 0))} -> Debby Pope | M20: 2.4 | N20: 4929 N Sawyer Ave | Chicago, IL 60625 | O20: =LEFT(N20, FIND("|", N20) - 1) -> 4929 N Sawyer Ave | P20: 33 | Q20: Rodriguez Sanchez, Rossana
A21: 609774 | B21: ALCOTT ES | C21: Louisa May Alcott College Preparatory ES | D21: 0.045 | E21: District | F21: Network 4 | G21: Jerry Travlos | H21: 58 | I21: Neutral | J21: 4b | K21: 4 | L21: {=INDEX('School Rep'!$A$2:$A$21, MATCH(J21, 'School Rep'!$B$2:$B$21, 0))} -> Ellen Rosenfeld | M21: 1.8 | N21: 2625 N Orchard St | Chicago, IL 60614 | O21: =LEFT(N21, FIND("|", N21) - 1) -> 2625 N Orchard St | P21: 43 | Q21: Knudsen, Timothy R.
A22: 610524 | B22: ALCOTT HS | C22: Louisa May Alcott College Preparatory HS | D22: 0.078 | E22: District | F22: Network 15 | G22: Michael Boraz | H22: 51 | I22: Neutral | J22: 4b | K22: 4 | L22: {=INDEX('School Rep'!$A$2:$A$21, MATCH(J22, 'School Rep'!$B$2:$B$21, 0))} -> Ellen Rosenfeld | M22: 2.4 | N22: 2957 N Hoyne Ave | Chicago, IL 60618 | O22: =LEFT(N22, FIND("|", N22) - 1) -> 2957 N Hoyne Ave | P22: 32 | Q22: Waguespack, Scott
A23: 609848 | B23: ALDRIDGE | C23: Ira F Aldridge Elementary School | D23: 0.179 | E23: District | F23: Network 13 | G23: Dr. Terrycita D. Perry | H23: 46 | I23: Neutral | J23: 10b | K23: 10 | L23: {=INDEX('School Rep'!$A$2:$A$21, MATCH(J23, 'School Rep'!$B$2:$B$21, 0))} -> Olga Bautista | M23: 3.2 | N23: 630 E 131st St | Chicago, IL 60827 | O23: =LEFT(N23, FIND("|", N23) - 1) -> 630 E 131st St | P23: 10 | Q23: Chico, Peter
A24: 609695 | B24: AMUNDSEN HS | C24: Roald Amundsen High School | D24: 0.064 | E24: District | F24: Network 14 | G24: Dr. Laura LeMone | H24: 56 | I24: Neutral | J24: 2b | K24: 2 | L24: {=INDEX('School Rep'!$A$2:$A$21, MATCH(J24, 'School Rep'!$B$2:$B$21, 0))} -> Debby Pope | M24: 1.4 | N24: 5110 N Damen Ave | Chicago, IL 60625 | O24: =LEFT(N24, FIND("|", N24) - 1) -> 5110 N Damen Ave | P24: 40 | Q24: Vasquez, Jr., Andre
A25: 609951 | B25: ARIEL | C25: Ariel Elementary Community Academy | D25: 0.07 | E25: District | F25: Network 9 | G25: Alene Mason | H25: 62 | I25: Strong | J25: 10a | K25: 10 | L25: {=INDEX('School Rep'!$A$2:$A$21, MATCH(J25, 'School Rep'!$B$2:$B$21, 0))} -> Che "Rhymefest" Smith | M25: 3.3 | N25: 1119 E 46th St | Chicago, IL 60653 | O25: =LEFT(N25, FIND("|", N25) - 1) -> 1119 E 46th St | P25: 4 | Q25: Robinson, Lamont J.
A26: 609777 | B26: ARMOUR | C26: Phillip D Armour Elementary School | D26: 0.078 | E26: District | F26: ISP | G26: #N/A | H26: 66 | I26: Strong | J26: 7b | K26: 7 | L26: {=INDEX('School Rep'!$A$2:$A$21, MATCH(J26, 'School Rep'!$B$2:$B$21, 0))} -> Yesenia Lopez | M26: 2.4 | N26: 950 W 33rd Pl | Chicago, IL 60608 | O26: =LEFT(N26, FIND("|", N26) - 1) -> 950 W 33rd Pl | P26: 11 | Q26: Lee, Nicole T.
A27: 609779 | B27: ARMSTRONG G | C27: George Armstrong International Studies ES | D27: 0.16 | E27: District | F27: ISP | G27: #N/A | H27: 67 | I27: Strong | J27: 2a | K27: 2 | L27: {=INDEX('School Rep'!$A$2:$A$21, MATCH(J27, 'School Rep'!$B$2:$B$21, 0))} -> Ebony DeBerry | M27: 2.8 | N27: 2110 W Greenleaf Ave | Chicago, IL 60645 | O27: =LEFT(N27, FIND("|", N27) - 1) -> 2110 W Greenleaf Ave | P27: 50 | Q27: Silverstein, Debra L.
A28: 400181 | B28: ART IN MOTION | C28: Art in Motion Charter School | D28: 0.141 | E28: Charter | F28: Charter | G28: #N/A | H28: 44 | I28: Neutral | J28: 10a | K28: 10 | L28: {=INDEX('School Rep'!$A$2:$A$21, MATCH(J28, 'School Rep'!$B$2:$B$21, 0))} -> Che "Rhymefest" Smith | M28: 3.5 | N28: 7415 S East End | Chicago, IL 60649 | O28: =LEFT(N28, FIND("|", N28) - 1) -> 7415 S East End | P28: 8 | Q28: Harris, Michelle A.
A29: 610287 | B29: ASHBURN | C29: Ashburn Community Elementary School | D29: 0.055 | E29: District | F29: Network 10 | G29: Mira Weber | H29: 51 | I29: Neutral | J29: 8a | K29: 8 | L29: {=INDEX('School Rep'!$A$2:$A$21, MATCH(J29, 'School Rep'!$B$2:$B$21, 0))} -> Angel Gutierrez | M29: 3.2 | N29: 8300 S St Louis Ave | Chicago, IL 60652 | O29: =LEFT(N29, FIND("|", N29) - 1) -> 8300 S St Louis Ave | P29: 18 | Q29: Curtis, Derrick G.
A30: 610268 | B30: ASHE | C30: Arthur R Ashe Elementary School | D30: 0.27 | E30: District | F30: Network 12 | G30: Shenethe Parks | H30: 57 | I30: Neutral | J30: 10b | K30: 10 | L30: {=INDEX('School Rep'!$A$2:$A$21, MATCH(J30, 'School Rep'!$B$2:$B$21, 0))} -> Olga Bautista | M30: 2.9 | N30: 8505 S Ingleside Ave | Chicago, IL 60619 | O30: =LEFT(N30, FIND("|", N30) - 1) -> 8505 S Ingleside Ave | P30: 8 | Q30: Harris, Michelle A.
A31: 400172 | B31: ASPIRA - BUSINESS & FINANCE HS | C31: ASPIRA Business and Finance | D31: 0.13 | E31: Charter | F31: Charter | G31: #N/A | H31: 20 | I31: Weak | J31: 3a | K31: 3 | L31: {=INDEX('School Rep'!$A$2:$A$21, MATCH(J31, 'School Rep'!$B$2:$B$21, 0))} -> Norma Rios-Sierra | M31: 3.2 | N31: 2989 N Milwaukee Ave | Chicago, IL 60618 | O31: =LEFT(N31, FIND("|", N31) - 1) -> 2989 N Milwaukee Ave | P31: 35 | Q31: Ramirez-Rosa, Carlos
A32: 400013 | B32: ASPIRA - EARLY COLLEGE HS | C32: ASPIRA Charter School - Early College High School | D32: 0.229 | E32: Charter | F32: Charter | G32: #N/A | H32: 69 | I32: Strong | J32: 3a | K32: 3 | L32: {=INDEX('School Rep'!$A$2:$A$21, MATCH(J32, 'School Rep'!$B$2:$B$21, 0))} -> Norma Rios-Sierra | M32: 3.3 | N32: 3986 W Barry Ave | Chicago, IL 60618 | O32: =LEFT(N32, FIND("|", N32) - 1) -> 3986 W Barry Ave | P32: 31 | Q32: Cardona, Jr., Felix
A33: 400017 | B33: ASPIRA - HAUGAN | C33: ASPIRA Charter School - Haugan Middle School | D33: 0.186 | E33: Charter | F33: Charter | G33: #N/A | H33: 43 | I33: Neutral | J33: 3a | K33: 3 | L33: {=INDEX('School Rep'!$A$2:$A$21, MATCH(J33, 'School Rep'!$B$2:$B$21, 0))} -> Norma Rios-Sierra | M33: 3.6 | N33: 3729 W Leland Ave | Chicago, IL 60625 | O33: =LEFT(N33, FIND("|", N33) - 1) -> 3729 W Leland Ave | P33: 33 | Q33: Rodriguez Sanchez, Rossana
A34: 609782 | B34: AUDUBON | C34: Audubon Elementary School | D34: 0.036 | E34: District | F34: Network 4 | G34: Jerry Travlos | H34: 69 | I34: Strong | J34: 4b | K34: 4 | L34: {=INDEX('School Rep'!$A$2:$A$21, MATCH(J34, 'School Rep'!$B$2:$B$21, 0))} -> Ellen Rosenfeld | M34: 1.5 | N34: 3500 N Hoyne Ave | Chicago, IL 60618 | O34: =LEFT(N34, FIND("|", N34) - 1) -> 3500 N Hoyne Ave | P34: 32 | Q34: Waguespack, Scott
A35: 610518 | B35: AUSTIN CCA HS | C35: Austin College and Career Academy High School | D35: 0.441 | E35: District | F35: Network 15 | G35: Michael Boraz | H35: 57 | I35: Neutral | J35: 5a | K35: 5 | L35: {=INDEX('School Rep'!$A$2:$A$21, MATCH(J35, 'School Rep'!$B$2:$B$21, 0))} -> Aaron "Jitu" Brown | M35: 3.7 | N35: 231 N Pine Ave | Chicago, IL 60644 | O35: =LEFT(N35, FIND("|", N35) - 1) -> 231 N Pine Ave | P35: 37 | Q35: Mitts, Emma
A36: 609786 | B36: AVALON PARK | C36: Avalon Park Elementary School | D36: 0.284 | E36: District | F36: Network 12 | G36: Shenethe Parks | H36: 63 | I36: Strong | J36: 10b | K36: 10 | L36: {=INDEX('School Rep'!$A$2:$A$21, MATCH(J36, 'School Rep'!$B$2:$B$21, 0))} -> Olga Bautista | M36: 2.8 | N36: 8045 S Kenwood Ave | Chicago, IL 60619 | O36: =LEFT(N36, FIND("|", N36) - 1) -> 8045 S Kenwood Ave | P36: 8 | Q36: Harris, Michelle A.
A37: 610325 | B37: AVONDALE-LOGANDALE | C37: Avondale-Logandale Elementary School | D37: 0.106 | E37: District | F37: Network 4 | G37: Jerry Travlos | H37: 41 | I37: Neutral | J37: 3a | K37: 3 | L37: {=INDEX('School Rep'!$A$2:$A$21, MATCH(J37, 'School Rep'!$B$2:$B$21, 0))} -> Norma Rios-Sierra | M37: 2.9 | N37: 3212 W George St | Chicago, IL 60618 | O37: =LEFT(N37, FIND("|", N37) - 1) -> 3212 W George St | P37: 35 | Q37: Ramirez-Rosa, Carlos
A38: 610544 | B38: AZUELA | C38: Mariano Azuela Elementary School | D38: 0.07 | E38: District | F38: Network 10 | G38: Mira Weber | H38: 47 | I38: Neutral | J38: 8a | K38: 8 | L38: {=INDEX('School Rep'!$A$2:$A$21, MATCH(J38, 'School Rep'!$B$2:$B$21, 0))} -> Angel Gutierrez | M38: 3.3 | N38: 4707 W Marquette Rd | Chicago, IL 60629 | O38: =LEFT(N38, FIND("|", N38) - 1) -> 4707 W Marquette Rd | P38: 23 | Q38: Tabares, Silvana
A39: 610563 | B39: BACK OF THE YARDS HS | C39: Back of the Yards IB High School | D39: 0.045 | E39: District | F39: ISP | G39: #N/A | H39: 38 | I39: Weak | J39: 8b | K39: 8 | L39: {=INDEX('School Rep'!$A$2:$A$21, MATCH(J39, 'School Rep'!$B$2:$B$21, 0))} -> Cydney Wallace | M39: 3.5 | N39: 2111 W 47th St | Chicago, IL 60609 | O39: =LEFT(N39, FIND("|", N39) - 1) -> 2111 W 47th St | P39: 12 | Q39: Ramirez, Julia M.
A40: 609788 | B40: BARNARD | C40: Alice L Barnard Computer Math & Science Ctr ES | D40: 0.092 | E40: District | F40: Network 10 | G40: Mira Weber | H40: 39 | I40: Weak | J40: 9b | K40: 9 | L40: {=INDEX('School Rep'!$A$2:$A$21, MATCH(J40, 'School Rep'!$B$2:$B$21, 0))} -> Therese Boyle | M40: 3 | N40: 10354 S Charles St | Chicago, IL 60643 | O40: =LEFT(N40, FIND("|", N40) - 1) -> 10354 S Charles St | P40: 19 | Q40: O'Shea, Matthew J.
A41: 609789 | B41: BARRY | C41: John Barry Elementary School | D41: 0.097 | E41: District | F41: Network 4 | G41: Jerry Travlos | H41: 43 | I41: Neutral | J41: 3a | K41: 3 | L41: {=INDEX('School Rep'!$A$2:$A$21, MATCH(J41, 'School Rep'!$B$2:$B$21, 0))} -> Norma Rios-Sierra | M41: 3.1 | N41: 2828 N Kilbourn Ave | Chicago, IL 60641 | O41: =LEFT(N41, FIND("|", N41) - 1) -> 2828 N Kilbourn Ave | P41: 31 | Q41: Cardona, Jr., Felix
A42: 609790 | B42: BARTON | C42: Clara Barton Elementary School | D42: 0.164 | E42: District | F42: Network 11 | G42: Latasha Geverola | H42: 46 | I42: Neutral | J42: 9a | K42: 9 | L42: {=INDEX('School Rep'!$A$2:$A$21, MATCH(J42, 'School Rep'!$B$2:$B$21, 0))} -> Frank Niles Thomas | M42: 3.4 | N42: 7650 S Wolcott Ave | Chicago, IL 60620 | O42: =LEFT(N42, FIND("|", N42) - 1) -> 7650 S Wolcott Ave | P42: 17 | Q42: Moore, David H.
...

Sheet Network Chiefs
A1: Network | B1: Network Chief
A2: Network 1 | B2: Julie McGlade
A3: Network 2 | B3: Marilou Rebolledo
A4: Network 3 | B4: Jennifer Farrell‐Rottman
A5: Network 4 | B5: Jerry Travlos
A6: Network 5 | B6: Shontae Higginbottom
A7: Network 6 | B7: Dr. Ethan Netterstrom
A8: Network 7 | B8: Dr. Antonio Acevedo
A9: Network 8 | B9: Gilberto Piedrahita
A10: Network 9 | B10: Alene Mason
A11: Network 10 | B11: Mira Weber
A12: Network 11 | B12: Latasha Geverola
... A19: Options | B19: Richard Smith

Sheet Sheet9
A1: school | B1: address | C1: network | D1: governance
A2: ACERO - BRIGHTON PARK | B2: 4420 S FAIRFIELD AVE | C2: Charter | D2: Charter
A3: ACERO - CISNEROS | B3: 2744 W PERSHING RD | C3: Charter | D3: Charter
A4: ACERO - CLEMENTE | B4: 2050 N NATCHEZ AVE | C4: Charter | D4: Charter
A5: ACERO - DE LA CRUZ | B5: 7416 N RIDGE AVE | C5: Charter | D5: Charter
A6: ACERO - DE LAS CASAS | B6: 1641 W 16TH ST | C6: Charter | D6: Charter
A7: ACERO - FUENTES | B7: 2845 W BARRY AVE | C7: Charter | D7: Charter
A8: ACERO - GARCIA HS | B8: 4248 W 47TH ST | C8: Charter | D8: Charter
A9: ACERO - IDAR | B9: 5050 S HOMAN AVE | C9: Charter | D9: Charter
A10: ACERO - MARQUEZ | B10: 2916 W 47TH ST | C10: Charter | D10: Charter
A11: ACERO - PAZ | B11: 2651 W 23RD ST | C11: Charter | D11: Charter
A12: ACERO - SANTIAGO | B12: 2510 W CORTEZ ST | C12: Charter | D12: Charter
... A99: CATALYST - MARIA | B99: 6727 S CALIFORNIA AVE | C99: Charter | D99: Charter
A100: CATALYST - MARIA (HS) | B100: #N/A | C100: Charter | D100: Charter
A101: CATHER | B101: 2908 W WASHINGTON BLVD | C101: Network 5 | D101: District
A102: CHALMERS | B102: 2745 W ROOSEVELT RD | C102: Network 5 | D102: District
A103: CHAPPELL | B103: 2135 W FOSTER AVE | C103: Network 2 | D103: District
A104: CHASE | B104: 2021 N POINT ST | C104: Network 4 | D104: District
A105: CHAVEZ | B105: 4747 S MARSHFIELD AVE | C105: ISP | D105: District
A106: CHIARTS HS | B106: 2714 W AUGUSTA BLVD | C106: Contract | D106: Contract
A107: CHICAGO ACADEMY ES | B107: 3400 N AUSTIN AVE | C107: AUSL | D107: District
A108: CHICAGO ACADEMY HS | B108: 3400 N AUSTIN AVE | C108: AUSL | D108: District
A109: CHICAGO AGRICULTURE HS | B109: 3857 W 111TH ST | C109: ISP | D109: District
A110: CHICAGO COLLEGIATE | B110: 11816 S INDIANA | C110: Charter | D110: Charter
A111: CHICAGO EXCEL HS | B111: 1257 W 111TH ST | C111: Options | D111: Contract
A112: CHICAGO MATH & SCIENCE HS | B112: 7212 N CLARK ST | C112: Charter | D112: Charter
... A349: LINCOLN | B349: 615 W KEMPER PL | C349: Network 4 | D349: District
A350: LINCOLN PARK ELC | B350: #N/A | C350: Network 4 | D350: District
A351: LINCOLN PARK HS | B351: 2001 N ORCHARD ST | C351: Network 14 | D351: District
A352: LINDBLOM HS | B352: 6130 S WOLCOTT AVE | C352: Network 16 | D352: District
A353: LITTLE BLACK PEARL HS | B353: 1060 E 47TH ST | C353: Options | D353: Contract
A354: LITTLE VILLAGE | B354: 2620 S LAWNDALE AVE | C354: ISP | D354: District
A355: LLOYD | B355: 2103 N LAMON AVE | C355: Network 3 | D355: District
A356: LOCKE A | B356: 3141 W JACKSON BLVD | C356: Charter | D356: Charter
A357: LOCKE J | B357: 2828 N OAK PARK AVE | C357: Network 3 | D357: District
A358: LORCA | B358: 3231 N SPRINGFIELD AVE | C358: Network 4 | D358: District
A359: LOVETT | B359: 6333 W BLOOMINGDALE AVE | C359: Network 3 | D359: District
A360: LOWELL | B360: 3320 W HIRSCH ST | C360: Network 5 | D360: District
A361: LOZANO | B361: 1501 N GREENVIEW AVE | C361: Network 6 | D361: District
A362: LYON | B362: 2941 N MCVICKER AVE | C362: Network 3 | D362: District
...

Sheet School Rep
A1: Rep | B1: ESB Subdist
A2: Jennifer Custer | B2: 1b | C2: CBOE1b
A3: Ebony DeBerry | B3: 2a | C3: CBOE2a
A4: Carlos Rivas | B4: 3b | C4: CBOE3b
A5: Ellen Rosenfeld | B5: 4b | C5: CBOE4b
A6: Aaron "Jitu" Brown | B6: 5a | C6: CBOE5a
A7: Jessica Biggs | B7: 6b | C7: CBOE6b
A8: Yesenia Lopez | B8: 7b | C8: CBOE7b
A9: Angel Gutierrez | B9: 8a | C9: CBOE8a
A10: Therese Boyle | B10: 9b | C10: CBOE9b
A11: Che "Rhymefest" Smith | B11: 10a | C11: CBOE10a
A12: Ed Bannon | B12: 1a | C12: CBOE1a
A13: Debby Pope | B13: 2b | C13: CBOE2b
... A21: Olga Bautista | B21: 10b | C21: CBOE10b

Sheet Sheet1
A1: School ID | B1: School Name | C1: School Address | D1: Ward | E1: 5Essentials | F1: Opportunity Index
A2: 400153 | B2: ACERO - BRIGHTON PARK | C2: 4420 S Fairfield Ave | Chicago, IL 60632
A3: 400101 | B3: ACERO - CISNEROS | C3: 2744 W Pershing Rd | Chicago, IL 60632
A4: 400120 | B4: ACERO - CLEMENTE | C4: 2050 N Natchez Ave | Chicago, IL 60707
A5: 400121 | B5: ACERO - DE LA CRUZ | C5: 7416 N Ridge Ave | Chicago, IL 60645
A6: 400081 | B6: ACERO - DE LAS CASAS | C6: 1641 W 16th St | Chicago, IL 60608
A7: 400082 | B7: ACERO - FUENTES | C7: 2845 W Barry Ave | Chicago, IL 60618
A8: 400085 | B8: ACERO - GARCIA HS | C8: 4248 W 47th St | Chicago, IL 60632
A9: 400112 | B9: ACERO - IDAR | C9: 5050 S Homan Ave | Chicago, IL 60632
A10: 400089 | B10: ACERO - MARQUEZ | C10: 2916 W 47th St | Chicago, IL 60632
A11: 400083 | B11: ACERO - PAZ | C11: 2651 W 23rd St | Chicago, IL 60608
A12: 400114 | B12: ACERO - SANTIAGO | C12: 2510 W Cortez St | Chicago, IL 60622
A13: 400149 | B13: ACERO - SOTO HS | C13: 5025 S St. Louis Ave | Chicago, IL 60632
... A648: 609973 | B648: ZAPATA | C648: 2728 S Kostner Ave | Chicago, IL 60623

Sheet Sheet6
A1: School Name | B1: Short Name | C1: ESB Subdist | D1: ESB Dist | E1: # Student Enrollment
A2: Acero Chtr Sch Network - Brighton Park Elem School | B2: ACERO - BRIGHTON PARK | C2: 7b | D2: 7 | E2: 534
A3: Acero Chtr Sch Network- Sandra Cisneros Elem School | B3: ACERO - CISNEROS | C3: 8b | D3: 8 | E3: 415
A4: Acero Chtr Sch Newtwork - Roberto Clemente Elem School | B4: ACERO - CLEMENTE | C4: 5a | D4: 5 | E4: 456
A5: Acero Chtr Sch Network- Sor Juana Ines de la Cruz K-12 | B5: ACERO - DE LA CRUZ | C5: 2a | D5: 2 | E5: 513
A6: Acero Chtr Sch Network - Bartolome de las Casas Elem Sch | B6: ACERO - DE LAS CASAS | C6: 7a | D6: 7 | E6: 244
A7: Acero Chtr Sch Network - Carlos Fuentes Elem School | B7: ACERO - FUENTES | C7: 3a | D7: 3 | E7: 401
A8: Acero Chtr Sch Network - Major Hector P Garcia MD H S | B8: ACERO - GARCIA HS | C8: 7b | D8: 7 | E8: 638
A9: Acero Chtr Sch Network - Jovita Idar Elem School | B9: ACERO - IDAR | C9: 7b | D9: 7 | E9: 521
A10: Acero Chtr Sch Network - Officer Donald J Marquez Elem | B10: ACERO - MARQUEZ | C10: 7b | D10: 7 | E10: 523
A11: Acero Chtr Sch Network - Octavio Paz Elem School | B11: ACERO - PAZ | C11: 7a | D11: 7 | E11: 173
A12: Acero Chtr Sch Network - Esmeralda Santiago Elem Sch | B12: ACERO - SANTIAGO | C12: 5a | D12: 5 | E12: 219
A13: Acero Chtr Sch Network Victoria Soto Campus | B13: ACERO - SOTO HS | C13: 7b | D13: 7 | E13: 560
... A44: Bateman Elem School | B44: BATEMAN | C44: 2b | D44: 2 | E44: 882
A45: Beard Elem School | B45: BEARD | C45: 1a | D45: 1
A46: Beasley Elem Magnet Academic Ctr | B46: BEASLEY | C46: 6b | D46: 6 | E46: 1046
A47: Beaubien Elem School | B47: BEAUBIEN | C47: 1a | D47: 1 | E47: 962
A48: Beethoven Elem School | B48: BEETHOVEN | C48: 6b | D48: 6 | E48: 259
A49: Beidler Elem School | B49: BEIDLER | C49: 5b | D49: 5 | E49: 259
A50: Belding Elem School | B50: BELDING | C50: 1b | D50: 1 | E50: 549
A51: Bell Elem School | B51: BELL | C51: 4b | D51: 4 | E51: 884
A52: Belmont-Cragin Elem School | B52: BELMONT-CRAGIN | C52: 3b | D52: 3 | E52: 479
A53: Bennett Elem School | B53: BENNETT | C53: 9b | D53: 9 | E53: 255
A54: Black Magnet Elem School | B54: BLACK | C54: 10b | D54: 10 | E54: 395
A55: Blaine Elem School | B55: BLAINE | C55: 4a | D55: 4 | E55: 635
A56: Blair Early Childhood Center | B56: BLAIR | C56: 8a | D56: 8
A57: Bogan High School | B57: BOGAN HS | C57: 8a | D57: 8 | E57: 643
A58: Bond Elem School | B58: BOND | C58: 9a | D58: 9 | E58: 227
A59: Mosaic School of Fine Arts | B59: MOSAIC | C59: #N/A | D59: #N/ | E59: 721
A60: Bouchet Elem Math & Science Acad | B60: BOUCHET | C60: 10a | D60: 10 | E60: 587
A61: Bowen High School | B61: BOWEN HS | C61: 10b | D61: 10 | E61: 192
A62: Bradwell Comm Arts & Sci Elem Sch | B62: BRADWELL | C62: 10a | D62: 10 | E62: 420
A63: Brennemann Elem School | B63: BRENNEMANN | C63: 4a | D63: 4 | E63: 435
A64: Brentano Elem Math & Science Acad | B64: BRENTANO | C64: 3a | D64: 3 | E64: 684
A65: Bridge Elem School | B65: BRIDGE | C65: 1b | D65: 1 | E65: 1080
A66: Bright Elem School | B66: BRIGHT | C66: 10b | D66: 10 | E66: 230
A67: Brighton Park Elem School | B67: BRIGHTON PARK | C67: 8b | D67: 8 | E67: 272
A68: Bronzeville Classical Elementary School | B68: BRONZEVILLE CLASSICAL | C68: 6b | D68: 6 | E68: 395
A69: Bronzeville Scholastic HS | B69: BRONZEVILLE HS | C69: 6b | D69: 6 | E69: 72
A70: Brooks College Prep Academy HS | B70: BROOKS HS | C70: 9b | D70: 9 | E70: 971
...
